<mujoco model="humanoid">

  <statistic extent="2" center="0 0 1"/>
  
  <option timestep="0.005"/>

  <visual>
    <map force="0.1" zfar="30"/>
    <rgba haze="0.15 0.25 0.35 1"/>
    <global offwidth="2560" offheight="1440" elevation="-20" azimuth="120"/>
  </visual>

  <statistic center="0 0 0.7"/>

  <asset>
    <texture type="skybox" builtin="gradient" rgb1=".3 .5 .7" rgb2="0 0 0" width="32" height="512"/>
    <texture name="body" type="cube" builtin="flat" mark="cross" width="128" height="128" rgb1="0.8 0.6 0.4" rgb2="0.8 0.6 0.4" markrgb="1 1 1"/>
    <material name="body" texture="body" texuniform="true" rgba="0.8 0.6 .4 1"/>
    <texture name="grid" type="2d" builtin="checker" width="512" height="512" rgb1=".1 .2 .3" rgb2=".2 .3 .4"/>
    <material name="grid" texture="grid" texrepeat="1 1" texuniform="true" reflectance=".2"/>
  </asset>

  <default>
    <motor ctrlrange="-1 1" ctrllimited="true"/>
    <default class="body">
      <geom  type="capsule" condim="1" friction="1.0 0.05 0.05" solimp=".9 .99 .003" solref=".015 1"/>
      <joint type="hinge" damping="0.1" stiffness="5" armature=".007" limited="true" solimplimit="0 .99 .01"/>
      <default class="small_joint">
        <joint damping="1.0" stiffness="2" armature=".006"/>
      </default>
      <default class="big_joint">
        <joint damping="5" stiffness="10" armature=".01"/>
      </default>
      <default class="bigger_stiff_joint">
        <joint damping="5" stiffness="20" armature=".01"/>
      </default>
      <default class="big_stiff_joint">
        <joint damping="5" stiffness="20" armature=".02"/>
      </default>
      <site size=".04" group="3"/>
      <default class="force-torque">
        <site type="box" size=".01 .01 .02" rgba="1 0 0 1" />
      </default>
      <default class="touch">
        <site type="capsule" rgba="0 0 1 .3"/>
      </default>
    </default>
  </default>

  <worldbody>
    <geom name="floor" type="plane" conaffinity="1" size="100 100 .2" material="grid"/>
    <body name="torso" pos="0 0 1.2" childclass="body">
      <light name="top" pos="0 0 2" mode="trackcom"/>
      <camera name="back" pos="-3 0 1" xyaxes="0 -1 0 1 0 2" mode="trackcom"/>
      <camera name="side" pos="0 -3 1" xyaxes="1 0 0 0 1 2" mode="trackcom"/>
      <freejoint name="root"/>
      <site name="root" class="force-torque"/>
      <geom name="torso" fromto="0 -.055 0 0 .055 0" size=".055"/>
      <!--geom name="upper_waist" fromto="-.01 -.045 -.10 -.01 .045 -.10" size=".045"/-->
      <site name="torso" class="touch" type="box" pos="0 0 -.05" size=".07 .12 .11"/>
      <body name="head" pos="0 0 .15">
        <geom name="head" type="sphere" size=".08"/>
        <site name="head" class="touch" type="sphere" size=".121"/>
        <camera name="egocentric" pos=".12 0 0" xyaxes="0 -1 0 .1 0 1" fovy="80"/>
      </body>
      <body name="lower_waist" pos="-.01 0 -.11" quat="1.000 0 -.002 0">
        <geom name="lower_waist" fromto="0 -.05 0 0 .05 0" size=".045"/>
        <site name="lower_waist" class="touch" size=".051 .05" zaxis="0 1 0"/>
        <!-- <joint name="abdomen_z" pos="0 0 .045" axis="0 0 1" range="-30 30" class="big_stiff_joint"/>
        <joint name="abdomen_y" pos="0 0 .045" axis="0 1 0" range="-50 20" class="bigger_stiff_joint"/> -->
        <body name="pelvis" pos="0 0 -.09" quat="1.000 0 -.002 0">
          <!-- <joint name="abdomen_x" pos="0 0 .08" axis="1 0 0" range="-20 20" class="big_joint"/> -->
          <geom name="butt" fromto="-.02 -.04 0 -.02 .04 0" size=".04"/>
          <site name="butt" class="touch" size=".081 .06" pos="-.02 0 0" zaxis="0 1 0"/>
          <body name="right_thigh" pos="0 -.06 -.03">
            <site name="right_hip" class="force-torque"/>
            <joint name="right_hip_x" axis="1 0 0" range="-30 10" class="big_joint"/>
            <joint name="right_hip_z" axis="0 0 1" range="-45 25" class="big_joint"/>
            <joint name="right_hip_y" axis="0 1 0" range="-90 40" class="bigger_stiff_joint"/>
            <geom name="right_thigh" fromto="0 0 0 0 .01 -.1" size=".04"/>
            <site name="right_thigh" class="touch" pos="0 .005 -.11" size=".051 .12" zaxis="0 -1 25"/>
            <body name="right_shin" pos="0 .01 -.16">
              <site name="right_knee" class="force-torque" pos="0 0 .02"/>
              <joint name="right_knee" pos="0 0 .02" axis="0 -1 0" range="-120 2"/>
              <geom name="right_shin" fromto="0 0 0 0 0 -.10"  size=".032"/>
              <site name="right_shin" class="touch" pos="0 0 -.1" size=".045 .1"/>
              <body name="right_foot" pos="0 0 -.12">
                <site name="right_ankle" class="force-torque"/>
                <joint name="right_ankle_y" pos="0 0 .085" axis="0 1 0" range="-20 20" class="small_joint"/>
                <joint name="right_ankle_x" pos="0 0 .085" axis="1 0 .5" range="-6 6" class="small_joint"/>
                <geom name="right_right_foot" fromto="-.015 -.01 0 .045 -.02 0" size=".015"/>
                <geom name="left_right_foot" fromto="-.015 0.01 0 .045  .02 0" size=".015"/>
                <site name="right_right_foot" class="touch" pos=".025 -.02 0" size=".025 .08" zaxis="15 -2 0"/>
                <site name="left_right_foot" class="touch" pos=".025 .01 0" size=".025 .08" zaxis="15 2 0"/>
              </body>
            </body>
          </body>
          <body name="left_thigh" pos="0 .06 -.03">
            <site name="left_hip" class="force-torque"/>
            <joint name="left_hip_x" axis="-1 0 0" range="-30 10" class="big_joint"/>
            <joint name="left_hip_z" axis="0 0 -1" range="-45 25" class="big_joint"/>
            <joint name="left_hip_y" axis="0 1 0" range="-90 40" class="bigger_stiff_joint"/>
            <geom name="left_thigh" fromto="0 0 0 0 -.01 -.1" size=".04"/>
            <site name="left_thigh" class="touch" pos="0 -.005 -.11" size=".051 .12" zaxis="0 1 25"/>
            <body name="left_shin" pos="0 -.01 -.16">
              <site name="left_knee" class="force-torque" pos="0 0 .02"/>
              <joint name="left_knee" pos="0 0 .02" axis="0 -1 0" range="-120 2"/>
              <geom name="left_shin" fromto="0 0 0 0 0 -.1"  size=".032"/>
              <site name="left_shin" class="touch"  pos="0 0 -.1" size=".045 .1"/>
              <body name="left_foot" pos="0 0 -.12">
                <site name="left_ankle" class="force-torque"/>
                <joint name="left_ankle_y" pos="0 0 .085" axis="0 1 0" range="-20 20" class="small_joint"/>
                <joint name="left_ankle_x" pos="0 0 .085" axis="1 0 .5" range="-6 6" class="small_joint"/>
                <geom name="left_left_foot" fromto="-.015 .01 0 .045 .02 0" size=".015"/>
                <geom name="right_left_foot" fromto="-.015 -.01 0 .045  -.02 0" size=".015"/>
                <site name="right_left_foot" class="touch" pos=".025 -.01 0" size=".025 .08" zaxis="15 -2 0"/>
                <site name="left_left_foot" class="touch" pos=".025 .03 0" size=".025 .08" zaxis="15 2 0"/>
              </body>
            </body>
          </body>
        </body>
      </body>
      <body name="right_upper_arm" pos="0 -.13 .01">
        <joint name="right_shoulder1" axis="2 1 1"  range="-70 50" class="big_joint"/>
        <joint name="right_shoulder2" axis="0 -1 1" range="-70 50" class="big_joint"/>
        <geom name="right_upper_arm" fromto="0 0 0 .04 -.06 -.06" size=".035"/>
        <site name="right_upper_arm" class="touch" pos=".06 -.06 -.06" size=".035 .12" zaxis="1 -1 -1"/>
        <body name="right_lower_arm" pos=".075 -.075 -.075">
          <joint name="right_elbow" axis="0 -1 1" range="-85 40" class="small_joint"/>
          <geom name="right_lower_arm" fromto=".01 .01 .01 .05 .05 .05" size=".03"/>
          <site name="right_lower_arm" class="touch" pos=".065 .065 .065" size=".03 .12" zaxis="1 1 1"/>
          <body name="right_hand" pos=".08 .08 .08">
            <geom name="right_hand" type="sphere" size=".035"/>
            <site name="right_hand" class="touch" type="sphere" size=".04"/>
          </body>
        </body>
      </body>
      <body name="left_upper_arm" pos="0 .13 .01">
        <joint name="left_shoulder1" axis="-2 1 -1" range="-70 50" class="big_joint"/>
        <joint name="left_shoulder2" axis="0 -1 -1" range="-70 50" class="big_joint"/>
        <geom name="left_upper_arm" fromto="0 0 0 .04 .06 -.06" size=".035"/>
        <site name="left_upper_arm" class="touch" pos=".06 .06 -.06" size=".035 .12" zaxis="1 1 -1"/>
        <body name="left_lower_arm" pos=".075 .075 -.075">
          <joint name="left_elbow" axis="0 -1 -1" range="-85 40" class="small_joint"/>
          <geom name="left_lower_arm" fromto=".01 -.01 .01 .05 -.05 .05" size=".03"/>
          <site name="left_lower_arm" class="touch" pos=".065 -.065 .065" size=".03 .12" zaxis="1 -1 1"/>
          <body name="left_hand" pos=".08 -.08 .08">
            <geom name="left_hand" type="sphere" size=".035"/>
            <site name="left_hand" class="touch" type="sphere" size=".035"/>
          </body>
        </body>
      </body>
    </body>
  </worldbody>

  <actuator>
    <!-- <motor name='abdomen_y'       gear='67.5' joint='abdomen_y'/>
    <motor name='abdomen_z'       gear='67.5' joint='abdomen_z'/>
    <motor name='abdomen_x'       gear='67.5' joint='abdomen_x'/> -->
    <motor name='right_hip_x'     gear='45.0' joint='right_hip_x'/>
    <motor name='right_hip_z'     gear='45.0' joint='right_hip_z'/>
    <motor name='right_hip_y'     gear='135.0' joint='right_hip_y'/>
    <motor name='right_knee'      gear='90.0' joint='right_knee'/>
    <motor name='right_ankle_x'   gear='22.5' joint='right_ankle_x'/>
    <motor name='right_ankle_y'   gear='22.5' joint='right_ankle_y'/>
    <motor name='left_hip_x'      gear='45.0' joint='left_hip_x'/>
    <motor name='left_hip_z'      gear='45.0' joint='left_hip_z'/>
    <motor name='left_hip_y'      gear='135.0' joint='left_hip_y'/>
    <motor name='left_knee'       gear='90.0' joint='left_knee'/>
    <motor name='left_ankle_x'    gear='22.5' joint='left_ankle_x'/>
    <motor name='left_ankle_y'    gear='22.5' joint='left_ankle_y'/>
    <motor name='right_shoulder1' gear='67.5' joint='right_shoulder1'/>
    <motor name='right_shoulder2' gear='67.5' joint='right_shoulder2'/>
    <motor name='right_elbow'     gear='45.0' joint='right_elbow'/>  
    <motor name='left_shoulder1'  gear='67.5' joint='left_shoulder1'/>
    <motor name='left_shoulder2'  gear='67.5' joint='left_shoulder2'/>
    <motor name='left_elbow'      gear='45.0' joint='left_elbow'/>
  </actuator>

  <sensor>
    <subtreelinvel name="torso_subtreelinvel" body="torso"/>
    <accelerometer name="torso_accel"    site="root"/>
    <velocimeter name="torso_vel"        site="root"/>
    <gyro name="torso_gyro"              site="root"/>

    <force name="left_ankle_force"       site="left_ankle"/>
    <force name="right_ankle_force"      site="right_ankle"/>
    <force name="left_knee_force"        site="left_knee"/>
    <force name="right_knee_force"       site="right_knee"/>
    <force name="left_hip_force"         site="left_hip"/>
    <force name="right_hip_force"        site="right_hip"/>

    <torque name="left_ankle_torque"     site="left_ankle"/>
    <torque name="right_ankle_torque"    site="right_ankle"/>
    <torque name="left_knee_torque"      site="left_knee"/>
    <torque name="right_knee_torque"     site="right_knee"/>
    <torque name="left_hip_torque"       site="left_hip"/>
    <torque name="right_hip_torque"      site="right_hip"/>

    <touch name="torso_touch"            site="torso"/>
    <touch name="head_touch"             site="head"/>
    <touch name="lower_waist_touch"      site="lower_waist"/>
    <touch name="butt_touch"             site="butt"/>
    <touch name="right_thigh_touch"      site="right_thigh"/>
    <touch name="right_shin_touch"       site="right_shin"/>
    <touch name="right_right_foot_touch" site="right_right_foot"/>
    <touch name="left_right_foot_touch"  site="left_right_foot"/>
    <touch name="left_thigh_touch"       site="left_thigh"/>
    <touch name="left_shin_touch"        site="left_shin"/>
    <touch name="right_left_foot_touch"  site="right_left_foot"/>
    <touch name="left_left_foot_touch"   site="left_left_foot"/>
    <touch name="right_upper_arm_touch"  site="right_upper_arm"/>
    <touch name="right_lower_arm_touch"  site="right_lower_arm"/>
    <touch name="right_hand_touch"       site="right_hand"/>
    <touch name="left_upper_arm_touch"   site="left_upper_arm"/>
    <touch name="left_lower_arm_touch"   site="left_lower_arm"/>
    <touch name="left_hand_touch"        site="left_hand"/>
  </sensor>

</mujoco>

